The purpose of the `try...catch` block in JavaScript is to handle exceptions or errors that may occur during the execution of a block of code. It provides a mechanism for graceful error handling and allows you to control the flow of your program in the event of an error.

Here's how the `try...catch` block works:

1. The `try` block: The code that potentially contains an error or exception is enclosed within the `try` block. It is the section of code where you anticipate an error might occur.

2. The `catch` block: If an error occurs within the `try` block, the execution is immediately transferred to the `catch` block. The `catch` block is responsible for handling the error. It receives the error object as a parameter, allowing you to access information about the error and perform appropriate actions.

3. Error handling: Within the `catch` block, you can include code to handle the error, such as logging an error message, displaying a user-friendly error message, or taking corrective actions. It gives you the opportunity to gracefully recover from the error or provide a fallback behavior.

Here's an example that demonstrates the usage of `try...catch`:

```
try {
  // Code that may potentially throw an error
  const result = someFunction();
  console.log(result);
} catch (error) {
  // Error handling
  console.log('An error occurred:', error.message);
}
```

The `try...catch` block is essential because it helps prevent unhandled exceptions from crashing your program and provides a way to gracefully handle errors. It allows you to maintain control over the execution flow even when errors occur. Instead of abruptly stopping the program, you can catch and handle errors, log them for debugging purposes, display user-friendly error messages, or execute fallback logic.

By utilizing `try...catch`, you can create more robust and reliable applications by effectively managing and responding to errors.